#VRML_SIM R2023b utf8

EXTERNPROTO "https://raw.githubusercontent.com/cyberbotics/webots/R2023a/projects/objects/backgrounds/protos/TexturedBackground.proto"
EXTERNPROTO "https://raw.githubusercontent.com/cyberbotics/webots/R2023a/projects/objects/backgrounds/protos/TexturedBackgroundLight.proto"
EXTERNPROTO "https://raw.githubusercontent.com/cyberbotics/webots/R2023a/projects/objects/floors/protos/RectangleArena.proto"
EXTERNPROTO "https://raw.githubusercontent.com/cyberbotics/webots/R2023a/projects/appearances/protos/Parquetry.proto"

WorldInfo {
  contactProperties [
    ContactProperties {
    }
  ]
}
Viewpoint {
  orientation -0.3028121845535118 0.1308566978198813 0.9440239962636575 2.366922109695997
  position 17.79693307514406 -26.984362975969187 20.805066621503983
}
TexturedBackground {
}
TexturedBackgroundLight {
}
RectangleArena {
  floorSize 10 10
  floorAppearance Parquetry {
    type "light strip"
  }
}
Robot {
  translation 2.364929315956209 -3.5027729076738803 0.083698017799859
  rotation -0.3489364945544686 -0.32870080854556166 -0.87760987986094 0.005297747156177691
  children [
    DEF Body Pose {
      rotation 0 0 1 -0.523595307179586
      children [
        Shape {
          appearance PBRAppearance {
            baseColor 0.333333 0.666667 1
            roughness 0.8
            metalness 0.2
          }
          geometry Cylinder {
            height 0.01
            radius 0.2
            subdivision 6
          }
        }
      ]
    }
    DEF LeftEye Pose {
      translation -0.05 0.18 0
      rotation 1 0 0 -1.5707953071795862
      children [
        Shape {
          appearance PBRAppearance {
            baseColor 0 0 0
          }
          geometry Cylinder {
            height 0.012
            radius 0.01
          }
        }
      ]
    }
    DEF RightEye Pose {
      translation 0.05 0.18 0
      rotation 1 0 0 -1.5707953071795862
      children [
        Shape {
          appearance PBRAppearance {
            baseColor 0 0 0
          }
          geometry Cylinder {
            height 0.012
            radius 0.01
          }
        }
      ]
    }
    DEF Leg0MR Pose {
      translation 0.2 0 0
      children [
        DEF JointBC Pose {
          children [
            Shape {
              geometry Cylinder {
                height 0.024
                radius 0.015
              }
            }
          ]
        }
        HingeJoint {
          jointParameters HingeJointParameters {
            position -0.10484575278384513
            axis 0 0 1
          }
          device [
            RotationalMotor {
              name "M_MR_COXA"
            }
            PositionSensor {
              name "S_MR_COXA"
            }
          ]
          endPoint Solid {
            translation 0.04972543585659477 -0.005232688493670282 0
            rotation 0 0 -1 0.1048457527838468
            children [
              DEF SHAPE_COXA Shape {
                appearance PBRAppearance {
                  baseColor 0.666667 1 1
                  roughness 1
                  metalness 0
                }
                geometry Box {
                  size 0.1 0.02 0.02
                }
              }
              HingeJoint {
                jointParameters HingeJointParameters {
                  position -0.24332072644235492
                  axis 0 1 0
                  anchor 0.05 0 0
                }
                device [
                  RotationalMotor {
                    name "M_MR_FEMUR"
                  }
                  PositionSensor {
                    name "S_MR_FEMUR"
                  }
                ]
                endPoint Solid {
                  translation 0.12764346202639226 0 0.019274148607815247
                  rotation 0 -1 0 0.24332072644235578
                  children [
                    DEF JointFT Pose {
                      translation 0.09 3.44753e-13 -1.87713e-07
                      rotation 0.9999999999944944 2.3464099999870814e-06 -2.3464099999870814e-06 1.5708
                      children [
                        Shape {
                          geometry Cylinder {
                            height 0.024
                            radius 0.015
                          }
                        }
                      ]
                    }
                    DEF SHAPE_FEMUR Shape {
                      appearance PBRAppearance {
                        baseColor 0.666667 1 1
                        roughness 1
                        metalness 0
                      }
                      geometry Box {
                        size 0.16 0.02 0.02
                      }
                    }
                    HingeJoint {
                      jointParameters HingeJointParameters {
                        position 1.5869303012629123
                        axis 0 1 0
                        anchor 0.09 0 0
                      }
                      device [
                        RotationalMotor {
                          name "M_MR_TIBIA"
                        }
                        PositionSensor {
                          name "S_MR_TIBIA"
                        }
                      ]
                      endPoint Solid {
                        translation 0.08887067078375868 0 -0.06999088951800334
                        rotation 0 1 0 1.5869303012629123
                        children [
                          DEF SHAPE_TIBIA Shape {
                            appearance PBRAppearance {
                              baseColor 0.666667 1 1
                              roughness 1
                              metalness 0
                            }
                            geometry Box {
                              size 0.12 0.02 0.02
                            }
                          }
                        ]
                        boundingObject USE SHAPE_TIBIA
                        physics Physics {
                          density -1
                          mass 0.6
                        }
                        linearVelocity -1.1987479648762907e-07 -3.048110258382422e-06 2.9396942589224736e-07
                        angularVelocity 2.1228217763543126e-06 5.529005654304987e-06 -0.0001390334792487527
                      }
                    }
                  ]
                  boundingObject USE SHAPE_FEMUR
                  physics Physics {
                    density -1
                    mass 0.8
                  }
                  linearVelocity 1.6676802604561714e-06 5.665336803513353e-06 7.936704140829987e-07
                  angularVelocity 1.4219840444331094e-06 5.541617854764225e-06 -0.000139171366955668
                }
              }
              DEF JointCF Pose {
                translation 0.05 0 0
                rotation 0.9999999999944944 2.3464099999870814e-06 -2.3464099999870814e-06 1.5708
                children [
                  Shape {
                    geometry Cylinder {
                      height 0.024
                      radius 0.015
                    }
                  }
                ]
              }
            ]
            boundingObject USE SHAPE_COXA
            physics Physics {
              density -1
              mass 0.8
            }
            linearVelocity 3.454210326965578e-06 1.7954167421583356e-05 1.4492825692976004e-06
            angularVelocity 9.451393160154452e-07 5.545691712171547e-06 -0.0001402025439496353
          }
        }
      ]
    }
    DEF Leg1FR Pose {
      translation 0.1 0.1732 0
      rotation 0 0 1 1.0472
      children [
        DEF JointBC Pose {
          children [
            Shape {
              geometry Cylinder {
                height 0.024
                radius 0.015
              }
            }
          ]
        }
        HingeJoint {
          jointParameters HingeJointParameters {
            position 0.04703637275903671
            axis 0 0 1
          }
          device [
            RotationalMotor {
              name "M_FR_COXA"
            }
            PositionSensor {
              name "S_FR_COXA"
            }
          ]
          endPoint Solid {
            translation 0.04994469968769823 0.0023509515319703736 0
            rotation 0 0 1 0.04703637275903672
            children [
              DEF SHAPE_COXA Shape {
                appearance PBRAppearance {
                  baseColor 0.666667 1 1
                  roughness 1
                  metalness 0
                }
                geometry Box {
                  size 0.1 0.02 0.02
                }
              }
              HingeJoint {
                jointParameters HingeJointParameters {
                  position -0.21795397627451316
                  axis 0 1 0
                  anchor 0.05 0 0
                }
                device [
                  RotationalMotor {
                    name "M_FR_FEMUR"
                  }
                  PositionSensor {
                    name "S_FR_FEMUR"
                  }
                ]
                endPoint Solid {
                  translation 0.12810735274790777 0 0.01729859666890435
                  rotation 0 -1 0 0.21795397627451235
                  children [
                    DEF JointFT Pose {
                      translation 0.09 3.44753e-13 -1.87713e-07
                      rotation 0.9999999999944944 2.3464099999870814e-06 -2.3464099999870814e-06 1.5708
                      children [
                        Shape {
                          geometry Cylinder {
                            height 0.024
                            radius 0.015
                          }
                        }
                      ]
                    }
                    DEF SHAPE_FEMUR Shape {
                      appearance PBRAppearance {
                        baseColor 0.666667 1 1
                        roughness 1
                        metalness 0
                      }
                      geometry Box {
                        size 0.16 0.02 0.02
                      }
                    }
                    HingeJoint {
                      jointParameters HingeJointParameters {
                        position 1.335236687589174
                        axis 0 1 0
                        anchor 0.09 0 0
                      }
                      device [
                        RotationalMotor {
                          name "M_FR_TIBIA"
                        }
                        PositionSensor {
                          name "S_FR_TIBIA"
                        }
                      ]
                      endPoint Solid {
                        translation 0.10633710443223564 0 -0.06806687166875107
                        rotation 0 1 0 1.3352366875891737
                        children [
                          DEF SHAPE_TIBIA Shape {
                            appearance PBRAppearance {
                              baseColor 0.666667 1 1
                              roughness 1
                              metalness 0
                            }
                            geometry Box {
                              size 0.12 0.02 0.02
                            }
                          }
                        ]
                        boundingObject USE SHAPE_TIBIA
                        physics Physics {
                          density -1
                          mass 0.6
                        }
                        linearVelocity 4.339942330753127e-06 4.054253451904057e-06 1.2172206994877662e-06
                        angularVelocity -1.1014033124925254e-06 6.688548890049746e-06 -2.6772338954340995e-05
                      }
                    }
                  ]
                  boundingObject USE SHAPE_FEMUR
                  physics Physics {
                    density -1
                    mass 0.8
                  }
                  linearVelocity 4.703099600740538e-06 9.848292722639295e-06 1.6556073710914804e-06
                  angularVelocity -5.130117110102896e-07 6.302178577891307e-06 -2.680394016758251e-05
                }
              }
              DEF JointCF Pose {
                translation 0.05 0 0
                rotation 0.9999999999944944 2.3464099999870814e-06 -2.3464099999870814e-06 1.5708
                children [
                  Shape {
                    geometry Cylinder {
                      height 0.024
                      radius 0.015
                    }
                  }
                ]
              }
            ]
            name "solid(1)"
            boundingObject USE SHAPE_COXA
            physics Physics {
              density -1
              mass 0.8
            }
            linearVelocity 4.423726549953582e-06 1.5698233362415798e-05 2.1013187323856637e-06
            angularVelocity -9.773901080558147e-08 6.030077205937993e-06 -2.6931977991181014e-05
          }
        }
      ]
    }
    DEF Leg2FL Pose {
      translation -0.1 0.1732 0
      rotation 0 0 1 2.0944
      children [
        DEF JointBC Pose {
          children [
            Shape {
              geometry Cylinder {
                height 0.024
                radius 0.015
              }
            }
          ]
        }
        HingeJoint {
          jointParameters HingeJointParameters {
            position 0.05675796179268026
            axis 0 0 1
          }
          device [
            RotationalMotor {
              name "M_FL_COXA"
            }
            PositionSensor {
              name "S_FL_COXA"
            }
          ]
          endPoint Solid {
            translation 0.04991948496251782 0.0028363746362339622 0
            rotation 0 0 1 0.056757961792680674
            children [
              DEF SHAPE_COXA Shape {
                appearance PBRAppearance {
                  baseColor 0.666667 1 1
                  roughness 1
                  metalness 0
                }
                geometry Box {
                  size 0.1 0.02 0.02
                }
              }
              HingeJoint {
                jointParameters HingeJointParameters {
                  position -0.28346607985662453
                  axis 0 1 0
                  anchor 0.05 0 0
                }
                device [
                  RotationalMotor {
                    name "M_FL_FEMUR"
                  }
                  PositionSensor {
                    name "S_FL_FEMUR"
                  }
                ]
                endPoint Solid {
                  translation 0.12680734372538138 0 0.022374806141084527
                  rotation 0 -1 0 0.28346607985662436
                  children [
                    DEF JointFT Pose {
                      translation 0.09 3.44753e-13 -1.87713e-07
                      rotation 0.9999999999944944 2.3464099999870814e-06 -2.3464099999870814e-06 1.5708
                      children [
                        Shape {
                          geometry Cylinder {
                            height 0.024
                            radius 0.015
                          }
                        }
                      ]
                    }
                    DEF SHAPE_FEMUR Shape {
                      appearance PBRAppearance {
                        baseColor 0.666667 1 1
                        roughness 1
                        metalness 0
                      }
                      geometry Box {
                        size 0.16 0.02 0.02
                      }
                    }
                    HingeJoint {
                      jointParameters HingeJointParameters {
                        position 1.819163995232319
                        axis 0 1 0
                        anchor 0.09 0 0
                      }
                      device [
                        RotationalMotor {
                          name "M_FL_TIBIA"
                        }
                        PositionSensor {
                          name "S_FL_TIBIA"
                        }
                      ]
                      endPoint Solid {
                        translation 0.07279245691825598 0 -0.06785204831904434
                        rotation 0 1 0 1.819163995232319
                        children [
                          DEF SHAPE_TIBIA Shape {
                            appearance PBRAppearance {
                              baseColor 0.666667 1 1
                              roughness 1
                              metalness 0
                            }
                            geometry Box {
                              size 0.12 0.02 0.02
                            }
                          }
                        ]
                        boundingObject USE SHAPE_TIBIA
                        physics Physics {
                          density -1
                          mass 0.6
                        }
                        linearVelocity 2.4117880049568114e-06 3.834139667303567e-06 4.015320482438518e-06
                        angularVelocity -3.077222720309065e-07 6.103247633601954e-06 3.359788869767513e-05
                      }
                    }
                  ]
                  boundingObject USE SHAPE_FEMUR
                  physics Physics {
                    density -1
                    mass 0.8
                  }
                  linearVelocity 3.891068187686534e-06 1.0175628399889507e-05 3.824712048725083e-06
                  angularVelocity -6.972385855225918e-07 5.622598444103132e-06 3.361342324252541e-05
                }
              }
              DEF JointCF Pose {
                translation 0.05 0 0
                rotation 0.9999999999944944 2.3464099999870814e-06 -2.3464099999870814e-06 1.5708
                children [
                  Shape {
                    geometry Cylinder {
                      height 0.024
                      radius 0.015
                    }
                  }
                ]
              }
            ]
            name "solid(2)"
            boundingObject USE SHAPE_COXA
            physics Physics {
              density -1
              mass 0.8
            }
            linearVelocity 6.025440994146374e-06 1.7194709827568233e-05 3.540055092088947e-06
            angularVelocity -2.360393361675858e-07 5.776606226947511e-06 3.338964690822578e-05
          }
        }
      ]
    }
    DEF Leg3ML Pose {
      translation -0.2 0 0
      rotation 0 0 1 -3.1415853071795863
      children [
        DEF JointBC Pose {
          children [
            Shape {
              geometry Cylinder {
                height 0.024
                radius 0.015
              }
            }
          ]
        }
        HingeJoint {
          jointParameters HingeJointParameters {
            position -0.1025147763579775
            axis 0 0 1
          }
          device [
            RotationalMotor {
              name "M_ML_COXA"
            }
            PositionSensor {
              name "S_ML_COXA"
            }
          ]
          endPoint Solid {
            translation 0.0497374980287692 -0.005116765564114416 0
            rotation 0 0 -1 0.1025147763579755
            children [
              DEF SHAPE_COXA Shape {
                appearance PBRAppearance {
                  baseColor 0.666667 1 1
                  roughness 1
                  metalness 0
                }
                geometry Box {
                  size 0.1 0.02 0.02
                }
              }
              HingeJoint {
                jointParameters HingeJointParameters {
                  position -0.24463207892015026
                  axis 0 1 0
                  anchor 0.05 0 0
                }
                device [
                  RotationalMotor {
                    name "M_ML_FEMUR"
                  }
                  PositionSensor {
                    name "S_ML_FEMUR"
                  }
                ]
                endPoint Solid {
                  translation 0.1276181200715038 0 0.01937594995259908
                  rotation 0 -1 0 0.2446320789201505
                  children [
                    DEF JointFT Pose {
                      translation 0.09 3.44753e-13 -1.87713e-07
                      rotation 0.9999999999944944 2.3464099999870814e-06 -2.3464099999870814e-06 1.5708
                      children [
                        Shape {
                          geometry Cylinder {
                            height 0.024
                            radius 0.015
                          }
                        }
                      ]
                    }
                    DEF SHAPE_FEMUR Shape {
                      appearance PBRAppearance {
                        baseColor 0.666667 1 1
                        roughness 1
                        metalness 0
                      }
                      geometry Box {
                        size 0.16 0.02 0.02
                      }
                    }
                    HingeJoint {
                      jointParameters HingeJointParameters {
                        position 1.5797946475833538
                        axis 0 1 0
                        anchor 0.09 0 0
                      }
                      device [
                        RotationalMotor {
                          name "M_ML_TIBIA"
                        }
                        PositionSensor {
                          name "S_ML_TIBIA"
                        }
                      ]
                      endPoint Solid {
                        translation 0.08937012604501392 0 -0.06999716607692655
                        rotation 0 1 0 1.5797946475833538
                        children [
                          DEF SHAPE_TIBIA Shape {
                            appearance PBRAppearance {
                              baseColor 0.666667 1 1
                              roughness 1
                              metalness 0
                            }
                            geometry Box {
                              size 0.12 0.02 0.02
                            }
                          }
                        ]
                        boundingObject USE SHAPE_TIBIA
                        physics Physics {
                          density -1
                          mass 0.6
                        }
                        linearVelocity -6.0724033072202005e-06 -6.5437872870896085e-06 6.20640978894542e-06
                        angularVelocity 2.245291671273142e-06 6.619470644813378e-06 0.0001918451566558672
                      }
                    }
                  ]
                  boundingObject USE SHAPE_FEMUR
                  physics Physics {
                    density -1
                    mass 0.8
                  }
                  linearVelocity -2.218744932597942e-06 5.353170663098331e-06 5.37949549695207e-06
                  angularVelocity 1.2483709166161323e-06 6.441813441762097e-06 0.00019204206677345153
                }
              }
              DEF JointCF Pose {
                translation 0.05 0 0
                rotation 0.9999999999944944 2.3464099999870814e-06 -2.3464099999870814e-06 1.5708
                children [
                  Shape {
                    geometry Cylinder {
                      height 0.024
                      radius 0.015
                    }
                  }
                ]
              }
            ]
            name "solid(3)"
            boundingObject USE SHAPE_COXA
            physics Physics {
              density -1
              mass 0.8
            }
            linearVelocity 1.7245832757153515e-06 2.2074543672593604e-05 4.430436543289474e-06
            angularVelocity 5.716909657621392e-07 6.356864068333001e-06 0.0001934846176919902
          }
        }
      ]
    }
    DEF Leg4HL Pose {
      translation -0.1 -0.1732 0
      rotation 0 0 -1 2.09439
      children [
        DEF JointBC Pose {
          children [
            Shape {
              geometry Cylinder {
                height 0.024
                radius 0.015
              }
            }
          ]
        }
        HingeJoint {
          jointParameters HingeJointParameters {
            position 0.047046167623994814
            axis 0 0 1
          }
          device [
            RotationalMotor {
              name "M_HL_COXA"
            }
            PositionSensor {
              name "S_HL_COXA"
            }
          ]
          endPoint Solid {
            translation 0.049944676658048866 0.0023514407334463703 0
            rotation 0 0 1 0.04704616762399498
            children [
              DEF SHAPE_COXA Shape {
                appearance PBRAppearance {
                  baseColor 0.666667 1 1
                  roughness 1
                  metalness 0
                }
                geometry Box {
                  size 0.1 0.02 0.02
                }
              }
              HingeJoint {
                jointParameters HingeJointParameters {
                  position -0.22756999201461484
                  axis 0 1 0
                  anchor 0.05 0 0
                }
                device [
                  RotationalMotor {
                    name "M_HL_FEMUR"
                  }
                  PositionSensor {
                    name "S_HL_FEMUR"
                  }
                ]
                endPoint Solid {
                  translation 0.12793740055552139 0 0.018048866852193812
                  rotation 0 -1 0 0.22756999201461436
                  children [
                    DEF JointFT Pose {
                      translation 0.09 3.44753e-13 -1.87713e-07
                      rotation 0.9999999999944944 2.3464099999870814e-06 -2.3464099999870814e-06 1.5708
                      children [
                        Shape {
                          geometry Cylinder {
                            height 0.024
                            radius 0.015
                          }
                        }
                      ]
                    }
                    DEF SHAPE_FEMUR Shape {
                      appearance PBRAppearance {
                        baseColor 0.666667 1 1
                        roughness 1
                        metalness 0
                      }
                      geometry Box {
                        size 0.16 0.02 0.02
                      }
                    }
                    HingeJoint {
                      jointParameters HingeJointParameters {
                        position 1.342508572825827
                        axis 0 1 0
                        anchor 0.09 0 0
                      }
                      device [
                        RotationalMotor {
                          name "M_HL_TIBIA"
                        }
                        PositionSensor {
                          name "S_HL_TIBIA"
                        }
                      ]
                      endPoint Solid {
                        translation 0.10584170236172205 0 -0.06818387247936725
                        rotation 0 1 0 1.3425085728258273
                        children [
                          DEF SHAPE_TIBIA Shape {
                            appearance PBRAppearance {
                              baseColor 0.666667 1 1
                              roughness 1
                              metalness 0
                            }
                            geometry Box {
                              size 0.12 0.02 0.02
                            }
                          }
                        ]
                        boundingObject USE SHAPE_TIBIA
                        physics Physics {
                          density -1
                          mass 0.6
                        }
                        linearVelocity 1.4185386658608178e-05 1.6485288544577238e-05 4.049125732448639e-06
                        angularVelocity 1.5320629560604883e-07 5.91315883473464e-06 4.6050962424743045e-05
                      }
                    }
                  ]
                  boundingObject USE SHAPE_FEMUR
                  physics Physics {
                    density -1
                    mass 0.8
                  }
                  linearVelocity 9.601127062877732e-06 1.900745163446329e-05 3.7574458242088284e-06
                  angularVelocity 1.5367924210464307e-07 5.912765122207189e-06 4.605102922722582e-05
                }
              }
              DEF JointCF Pose {
                translation 0.05 0 0
                rotation 0.9999999999944944 2.3464099999870814e-06 -2.3464099999870814e-06 1.5708
                children [
                  Shape {
                    geometry Cylinder {
                      height 0.024
                      radius 0.015
                    }
                  }
                ]
              }
            ]
            name "solid(4)"
            boundingObject USE SHAPE_COXA
            physics Physics {
              density -1
              mass 0.8
            }
            linearVelocity 4.28359777695878e-06 2.1755364190403635e-05 3.4626836805528355e-06
            angularVelocity 1.5386118373227674e-07 5.912614435367142e-06 4.6051444781670015e-05
          }
        }
      ]
    }
    DEF Leg5HR Pose {
      translation 0.1 -0.1732 0
      rotation 0 0 -1 1.0472
      children [
        DEF JointBC Pose {
          children [
            Shape {
              geometry Cylinder {
                height 0.024
                radius 0.015
              }
            }
          ]
        }
        HingeJoint {
          jointParameters HingeJointParameters {
            position 0.05674697833656772
            axis 0 0 1
          }
          device [
            RotationalMotor {
              name "M_HR_COXA"
            }
            PositionSensor {
              name "S_HR_COXA"
            }
          ]
          endPoint Solid {
            translation 0.04991951611270237 0.0028358263475906005 0
            rotation 0 0 1 0.0567469783365665
            children [
              DEF SHAPE_COXA Shape {
                appearance PBRAppearance {
                  baseColor 0.666667 1 1
                  roughness 1
                  metalness 0
                }
                geometry Box {
                  size 0.1 0.02 0.02
                }
              }
              HingeJoint {
                jointParameters HingeJointParameters {
                  position -0.2630252048317514
                  axis 0 1 0
                  anchor 0.05 0 0
                }
                device [
                  RotationalMotor {
                    name "M_HR_FEMUR"
                  }
                  PositionSensor {
                    name "S_HR_FEMUR"
                  }
                ]
                endPoint Solid {
                  translation 0.1272486268689168 0 0.02080023189454525
                  rotation 0 -1 0 0.26302520483175146
                  children [
                    DEF JointFT Pose {
                      translation 0.09 3.44753e-13 -1.87713e-07
                      rotation 0.9999999999944944 2.3464099999870814e-06 -2.3464099999870814e-06 1.5708
                      children [
                        Shape {
                          geometry Cylinder {
                            height 0.024
                            radius 0.015
                          }
                        }
                      ]
                    }
                    DEF SHAPE_FEMUR Shape {
                      appearance PBRAppearance {
                        baseColor 0.666667 1 1
                        roughness 1
                        metalness 0
                      }
                      geometry Box {
                        size 0.16 0.02 0.02
                      }
                    }
                    HingeJoint {
                      jointParameters HingeJointParameters {
                        position 1.8017274773468959
                        axis 0 1 0
                        anchor 0.09 0 0
                      }
                      device [
                        RotationalMotor {
                          name "M_HR_TIBIA"
                        }
                        PositionSensor {
                          name "S_HR_TIBIA"
                        }
                      ]
                      endPoint Solid {
                        translation 0.07397811617993312 0 -0.06814175840742799
                        rotation 0 1 0 1.8017274773468959
                        children [
                          DEF SHAPE_TIBIA Shape {
                            appearance PBRAppearance {
                              baseColor 0.666667 1 1
                              roughness 1
                              metalness 0
                            }
                            geometry Box {
                              size 0.12 0.02 0.02
                            }
                          }
                        ]
                        boundingObject USE SHAPE_TIBIA
                        physics Physics {
                          density -1
                          mass 0.6
                        }
                        linearVelocity 6.173084351538483e-07 1.49990095249757e-06 1.7915560462256944e-06
                        angularVelocity -1.3372359510484344e-07 5.370013130733533e-06 -4.6560931918657845e-05
                      }
                    }
                  ]
                  boundingObject USE SHAPE_FEMUR
                  physics Physics {
                    density -1
                    mass 0.8
                  }
                  linearVelocity 1.3796390502381565e-06 7.878904892681041e-06 1.9020946772140266e-06
                  angularVelocity -4.548068814642513e-07 5.200540609556596e-06 -4.660390252266713e-05
                }
              }
              DEF JointCF Pose {
                translation 0.05 0 0
                rotation 0.9999999999944944 2.3464099999870814e-06 -2.3464099999870814e-06 1.5708
                children [
                  Shape {
                    geometry Cylinder {
                      height 0.024
                      radius 0.015
                    }
                  }
                ]
              }
            ]
            name "solid(5)"
            boundingObject USE SHAPE_COXA
            physics Physics {
              density -1
              mass 0.8
            }
            linearVelocity 3.266773988877365e-06 1.5217392302172322e-05 2.149998872590544e-06
            angularVelocity -6.429171198638052e-08 5.4792616447342204e-06 -4.6688642485530094e-05
          }
        }
      ]
    }
  ]
  boundingObject USE Body
  physics Physics {
    density 500
  }
  controller "hexapod"
  linearVelocity 4.183533996458329e-06 2.1723497892737783e-05 2.8488372322104497e-06
  angularVelocity 2.4458014219408185e-07 5.811093719196706e-06 -1.1169636301963633e-05
}
